Workbook

Sheet Year1
A1: Principal Investigator: | C1: Sylvia Bradshaw | F1: Start Date: | G1: 45474 | H1: End Date: | I1: 45838 | J1: Year 1
A2: Title: | B2: NSF GRANTED - University of Idaho | F2: * Input data into Year 1. If the effort (% or hours/week) is the same from year to year, it will auto-fill remaining years. If different, manually adjust effort in subsequent years.
A3: A. Senior Personnel | C3: Role | D3: Months | E3: % Effort | F3: Base Salary | G3: Salary Request | H3: % Fringe | I3: Benefits | J3: Total
A4: Sylvia Bradshaw | C4: PI | D4: =12*E4 -> 0.6 | E4: 0.05 | F4: 115000 | G4: =SUM(F4/12)*D4 -> 5750 | H4: 0.235 | I4: =(G4*H4)+(21138*E4) -> 2408.15 | J4: =G4+I4 -> 8158.15
A5: Katie Gomez | D5: =12*E5 -> 1.8 | E5: 0.15 | F5: 77000 | G5: =SUM(F5/12)*D5 -> 11550 | H5: 0.235 | I5: =(G5*H5)+(21138*E5) -> 5884.95 | J5: =G5+I5 -> 17434.95
A6: TBD - Data Analyst | D6: =12*E6 -> 12 | E6: 1 | F6: 60000 | G6: =SUM(F6/12)*D6 -> 60000 | H6: 0.235 | I6: =(G6*H6)+(21138*E6) -> 35238 | J6: =G6+I6 -> 95238
A7: Name here (e.g., co-PI, Sr. Personnel) | D7: =12*E7 -> 0 | G7: =SUM(F7/9)*D7 -> 0 | H7: 0.235 | I7: =G7*H7 -> 0 | J7: =G7+I7 -> 0
A8: Senior Personnel Subtotal | G8: =SUM(G4:G7) -> 77300 | I8: =G8*H8 -> 0
A9: B. Other Personnel | C9: Role | D9: Months | E9: % Effort | F9: Base Salary | G9: Salary Request | H9: % Fringe | I9: Benefits | J9: Total
A10: Postdoctoral Scholars (*faculty benefit rate) | D10: =12*E10 -> 0 | G10: =SUM(F10/9)*D10 -> 0 | H10: 0.235 | I10: =G10*H10 -> 0 | J10: =G10+I10 -> 0
A11: Other Professionals (**staff benefit rate) | D11: =12*E11 -> 0 | G11: =F11*E11 -> 0 | H11: 0.235 | I11: =(G11*H11)+(21138*E11) -> 0 | J11: =G11+I11 -> 0
A12: Other Professionals (**staff benefit rate) | D12: =12*E12 -> 0 | G12: =F12*E12 -> 0 | H12: 0.235 | I12: =(G12*H12)+(21138*E12) -> 0 | J12: =G12+I12 -> 0
C13: How Many | D13: # of wks | E13: Hrs/wk | F13: Base Rate | G13: Wage Request | H13: % Fringe | I13: Benefits | J13: Total
A14: Graduate Students (*student benefit rate) | G14: =F14*E14*D14+C14 -> 0 | H14: 0.07 | I14: =G14*H14 -> 0 | J14: =G14+I14 -> 0
A15: Undergraduate Students (*student benefit rate) | C15: 1 | D15: 42 | E15: 10 | F15: 14 | G15: =C15*D15*E15*F15 -> 5880 | H15: 0.07 | I15: =G15*H15 -> 411.6 | J15: =G15+I15 -> 6291.6
A16: Administrative/Clerical (**non-Student benefit rate) | G16: =F16*E16*D16+C16 -> 0 | H16: 0.095 | I16: =G16*H16 -> 0 | J16: =G16+I16 -> 0
A17: Other (**non-student benefit rate) | G17: =F17*E17*D17+C17 -> 0 | H17: 0.095 | I17: =G17*H17 -> 0 | J17: =G17+I17 -> 0
A18: Other Personnel Subtotal | G18: =SUM(G10:G17) -> 5880
A19: C. Fringe Benefits
G20: =SUM(G8+G18) -> 83180 | H20: + | I20: =SUM(I4:I19) -> 43942.7 | J20: =SUM(J4:J19) -> 127122.7
A21: Subtotals | G21: Total Salary/Wage | I21: Total Benefits = | J21: Total SWB
A22: Additional Direct Costs | C22: (Enter for EVERY year that applies)
A23: D. Equipment | C23: (Note: Minimum $5,000 per item)
A24: Add description of equipment here… | J24: 0
J25: 0
J26: 0
J27: 0
I28: Total | J28: =SUM(J24:J27) -> 0
A29: E. Travel
A30: 1. Travel to UI for 3 people - Each person will have airfare $500, hotel 2 nights $450, per diem $175, $1,125 each | J30: 3375
A31: 2. Data Analyst - NCURA trainings- Fundamentals and NCURA Regional Meeting - $2,500 each | J31: 5000
J32: 0
I33: Total | J33: =SUM(J30:J32) -> 8375
A34: F. Participant Support Costs
A35: Number of Participants – Add # to yellow cell to the right | I35: 8 | J35: 0
A36: Stipends – Detail here, if applies | J36: 0
A37: Travel – Detail here, if applies | J37: 0
A38: Subsistence – Per diem. Detail here, if applies | J38: 0
A39: Other – PUI Committee Convening - Travel stipends up to $1,250/participant, 8 participants | J39: =1250*8 -> 10000
I40: Total | J40: =SUM(J35:J39) -> 10000
...

Sheet Year2
A1: Principal Investigator: | C1: =Year1!C1 -> Sylvia Bradshaw | F1: Start Date: | G1: =DATE(YEAR('All Years'!B21)+'All Years'!B18,MONTH('All Years'!B21),DAY('All Years'!B21)) -> 45839 | H1: End Date: | I1: =DATE(YEAR('All Years'!B22)+'All Years'!B18,MONTH('All Years'!B22),DAY('All Years'!B22)) -> 46203 | J1: Year 2
A2: Title: | B2: =Year1!B2 -> NSF GRANTED - University of Idaho
A3: A. Senior Personnel | C3: Role | D3: Months | E3: % Effort | F3: Base Salary | G3: Salary Request | H3: % Fringe | I3: Benefits | J3: Total
A4: =Year1!A4 -> Sylvia Bradshaw | C4: =Year1!C4 -> PI | D4: =12*E4 -> 0.6 | E4: =Year1!E4 -> 0.05 | F4: =Year1!F4*(1+'All Years'!C20) -> 118450 | G4: =SUM(F4/12)*D4 -> 5922.5 | H4: 0.235 | I4: =(G4*H4)+(21138*E4) -> 2448.6875 | J4: =G4+I4 -> 8371.1875
A5: =Year1!A5 -> Katie Gomez | C5: =Year1!C5 -> 0 | D5: =12*E5 -> 1.8 | E5: =Year1!E5 -> 0.15 | F5: =Year1!F5*(1+'All Years'!C20) -> 79310 | G5: =SUM(F5/12)*D5 -> 11896.5 | H5: 0.235 | I5: =(G5*H5)+(21138*E5) -> 5966.3775 | J5: =G5+I5 -> 17862.877
A6: =Year1!A6 -> TBD - Data Analyst | C6: =Year1!C6 -> 0 | D6: =12*E6 -> 12 | E6: =Year1!E6 -> 1 | F6: =Year1!F6*(1+'All Years'!C20) -> 61800 | G6: =SUM(F6/12)*D6 -> 61800 | H6: 0.235 | I6: =(G6*H6)+(21138*E6) -> 35661 | J6: =G6+I6 -> 97461
A7: =Year1!A7 -> Name here (e.g., co-PI, Sr. Personnel) | C7: =Year1!C7 -> 0 | D7: =12*E7 -> 0 | E7: =Year1!E7 -> 0 | F7: =Year1!F7*(1+'All Years'!C20) -> 0 | G7: =SUM(F7/9)*D7 -> 0 | H7: 0.235 | I7: =G7*H7 -> 0 | J7: =G7+I7 -> 0
A8: Senior Personnel Subtotal | G8: =SUM(G4:G7) -> 79619
A9: B. Other Personnel | C9: Role | D9: Months | E9: % Effort | F9: Base Salary | G9: Salary Request | H9: % Fringe | I9: Benefits | J9: Total
A10: =Year1!A10 -> Postdoctoral Scholars (*faculty benefit rate) | C10: =Year1!C10 -> 0 | D10: =12*E10 -> 0 | E10: =Year1!E10 -> 0 | F10: =Year1!F10*(1+'All Years'!C20) -> 0 | G10: =SUM(F10/9)*D10 -> 0 | H10: 0.235 | I10: =G10*H10 -> 0 | J10: =G10+I10 -> 0
A11: =Year1!A11 -> Other Professionals (**staff benefit rate) | C11: =Year1!C11 -> 0 | D11: =12*E11 -> 0 | E11: =Year1!E11 -> 0 | F11: =Year1!F11*(1+'All Years'!C20) -> 0 | G11: =F11*E11 -> 0 | H11: 0.235 | I11: =(G11*H11)+(21138*E11) -> 0 | J11: =G11+I11 -> 0
A12: =Year1!A12 -> Other Professionals (**staff benefit rate) | C12: =Year1!C12 -> 0 | D12: =12*E12 -> 0 | E12: =Year1!E12 -> 0 | F12: =Year1!F12*(1+'All Years'!C20) -> 0 | G12: =F12*E12 -> 0 | H12: 0.235 | I12: =(G12*H12)+(21138*E12) -> 0 | J12: =G12+I12 -> 0
C13: How Many | D13: # of wks | E13: Hrs/wk | F13: Base Rate | G13: Wage Request | H13: % Fringe | I13: Benefits | J13: Total
A14: =Year1!A14 -> Graduate Students (*student benefit rate) | C14: =Year1!C14 -> 0 | D14: =Year1!D14 -> 0 | E14: =Year1!E14 -> 0 | F14: =Year1!F14*(1+'All Years'!C20) -> 0 | G14: =F14*E14*D14*C14 -> 0 | H14: 0.07 | I14: =G14*H14 -> 0 | J14: =G14+I14 -> 0
A15: =Year1!A15 -> Undergraduate Students (*student benefit rate) | C15: =Year1!C15 -> 1 | D15: =Year1!D15 -> 42 | E15: =Year1!E15 -> 10 | F15: 15 | G15: =C15*D15*E15*F15 -> 6300 | H15: 0.07 | I15: =G15*H15 -> 441 | J15: =G15+I15 -> 6741
A16: =Year1!A16 -> Administrative/Clerical (**non-Student benefit rate) | C16: =Year1!C16 -> 0 | D16: =Year1!D16 -> 0 | E16: =Year1!E16 -> 0 | F16: =Year1!F16*(1+'All Years'!C20) -> 0 | G16: =F16*E16*D16*C16 -> 0 | H16: 0.095 | I16: =G16*H16 -> 0
A17: =Year1!A17 -> Other (**non-student benefit rate) | C17: =Year1!C17 -> 0 | D17: =Year1!D17 -> 0 | E17: =Year1!E17 -> 0 | F17: =Year1!F17*(1+'All Years'!C20) -> 0 | G17: =F17*E17*D17*C17 -> 0 | H17: 0.095 | I17: =G17*H17 -> 0
A18: Other Personnel Subtotal | G18: =SUM(G10:G17) -> 6300
A19: C. Fringe Benefits
G20: =G8+G18 -> 85919 | H20: + | I20: =SUM(I4:I19) -> 44517.065 | J20: =SUM(J4:J19) -> 130436.07
A21: Subtotals | G21: Total Salary/Wage | I21: Total Benefits = | J21: Total SWB
A22: Additional Direct Costs | C22: (Enter for EVERY year that applies)
A23: D. Equipment | C23: (Note: Minimum $5,000 per item)
A24: Add description of equipment here… | J24: 0
J25: 0
J26: 0
J27: 0
I28: Total | J28: =SUM(J24:J27) -> 0
A29: E. Travel
A30: 1. Travel to UI for 3 people - Each person will have airfare $500, hotel 2 nights $450, per diem $175, $1,125 each | J30: 3375
A31: 2. Data Analyst - NCURA trainings- Fundamentals and NCURA Regional Meeting - $2,500 each | J31: 5000
J32: 0
I33: Total | J33: =SUM(J30:J32) -> 8375
A34: F. Participant Support Costs for Students
A35: Number of Participants – Add # to yellow cell to the right | J35: 0
A36: Stipends – Detail here, if applies | J36: 0
A37: Travel – Detail here, if applies | J37: 0
A38: Subsistence – Per diem. Detail here, if applies | J38: 0
A39: Other – PUI Committee Convening - Travel stipends up to $1,250/participant, 8 participants | J39: 10000
I40: Total | J40: =SUM(J35:J39) -> 10000
...

Sheet Year3
A1: Principal Investigator: | C1: =Year1!C1 -> Sylvia Bradshaw | F1: Start Date: | G1: =DATE(YEAR('All Years'!C21)+'All Years'!C18,MONTH('All Years'!C21),DAY('All Years'!C21)) -> 46204 | H1: End Date: | I1: =DATE(YEAR('All Years'!C22)+'All Years'!C18,MONTH('All Years'!C22),DAY('All Years'!C22)) -> 46568 | J1: Year 3
A2: Title: | B2: =Year1!B2 -> NSF GRANTED - University of Idaho
A3: A. Senior Personnel | C3: Role | D3: Months | E3: % Effort | F3: Base Salary | G3: Salary Request | H3: % Fringe | I3: Benefits | J3: Total
A4: =Year1!A4 -> Sylvia Bradshaw | C4: =Year1!C4 -> PI | D4: =12*E4 -> 1.5 | E4: 0.125 | F4: =Year2!F4*(1+'All Years'!D20) -> 122003.5 | G4: =SUM(F4/12)*D4 -> 15250.438 | H4: 0.235 | I4: =(G4*H4)+(21138*E4) -> 6226.1028 | J4: =G4+I4 -> 21476.54
A5: =Year1!A5 -> Katie Gomez | C5: =Year1!C5 -> 0 | D5: =12*E5 -> 1.8 | E5: =Year1!E5 -> 0.15 | F5: =Year2!F5*(1+'All Years'!D20) -> 81689.3 | G5: =SUM(F5/12)*D5 -> 12253.395 | H5: 0.235 | I5: =(G5*H5)+(21138*E5) -> 6050.2478 | J5: =G5+I5 -> 18303.643
A6: =Year1!A6 -> TBD - Data Analyst | C6: =Year1!C6 -> 0 | D6: =12*E6 -> 12 | E6: =Year1!E6 -> 1 | F6: =Year2!F6*(1+'All Years'!D20) -> 63654 | G6: =SUM(F6/12)*D6 -> 63654 | H6: 0.235 | I6: =(G6*H6)+(21138*E6) -> 36096.69 | J6: =G6+I6 -> 99750.69
A7: =Year1!A7 -> Name here (e.g., co-PI, Sr. Personnel) | C7: =Year1!C7 -> 0 | D7: =12*E7 -> 0 | E7: =Year1!E7 -> 0 | F7: =Year2!F7*(1+'All Years'!D20) -> 0 | G7: =SUM(F7/9)*D7 -> 0 | H7: 0.235 | I7: =G7*H7 -> 0 | J7: =G7+I7 -> 0
A8: Senior Personnel Subtotal | G8: =SUM(G4:G7) -> 91157.832
A9: B. Other Personnel | C9: Role | D9: Months | E9: % Effort | F9: Base Salary | G9: Salary Request | H9: % Fringe | I9: Benefits | J9: Total
A10: =Year1!A10 -> Postdoctoral Scholars (*faculty benefit rate) | C10: =Year1!C10 -> 0 | D10: =12*E10 -> 0 | E10: =Year1!E10 -> 0 | F10: =Year2!F10*(1+'All Years'!D20) -> 0 | G10: =SUM(F10/9)*D10 -> 0 | H10: 0.235 | I10: =G10*H10 -> 0 | J10: =G10+I10 -> 0
A11: =Year1!A11 -> Other Professionals (**staff benefit rate) | C11: =Year1!C11 -> 0 | D11: =12*E11 -> 0 | E11: =Year1!E11 -> 0 | F11: =Year2!F11*(1+'All Years'!D20) -> 0 | G11: =F11*E11 -> 0 | H11: 0.235 | I11: =(G11*H11)+(21138*E11) -> 0 | J11: =G11+I11 -> 0
A12: =Year1!A12 -> Other Professionals (**staff benefit rate) | C12: =Year1!C12 -> 0 | D12: =12*E12 -> 0 | E12: =Year1!E12 -> 0 | F12: =Year2!F12*(1+'All Years'!D20) -> 0 | G12: =F12*E12 -> 0 | H12: 0.235 | I12: =(G12*H12)+(21138*E12) -> 0 | J12: =G12+I12 -> 0
C13: How Many | D13: # of wks | E13: Hrs/wk | F13: Base Rate | G13: Wage Request | H13: % Fringe | I13: Benefits | J13: Total
A14: =Year1!A14 -> Graduate Students (*student benefit rate) | C14: =Year1!C14 -> 0 | D14: =Year1!D14 -> 0 | E14: =Year1!E14 -> 0 | F14: =Year2!F14*(1+'All Years'!D20) -> 0 | G14: =F14*E14*D14*C14 -> 0 | H14: 0.07 | I14: =G14*H14 -> 0 | J14: =G14+I14 -> 0
A15: =Year1!A15 -> Undergraduate Students (*student benefit rate) | C15: =Year1!C15 -> 1 | D15: =Year1!D15 -> 42 | E15: =Year1!E15 -> 10 | F15: 16 | G15: =C15*D15*E15*F15 -> 6720 | H15: 0.07 | I15: =G15*H15 -> 470.4 | J15: =G15+I15 -> 7190.4
A16: =Year1!A16 -> Administrative/Clerical (**non-Student benefit rate) | C16: =Year1!C16 -> 0 | D16: =Year1!D16 -> 0 | E16: =Year1!E16 -> 0 | F16: =Year2!F16*(1+'All Years'!D20) -> 0 | G16: =F16*E16*D16*C16 -> 0 | H16: 0.095 | I16: =G16*H16 -> 0 | J16: =G16+I16 -> 0
A17: =Year1!A17 -> Other (**non-student benefit rate) | C17: =Year1!C17 -> 0 | D17: =Year1!D17 -> 0 | E17: =Year1!E17 -> 0 | F17: =Year2!F17*(1+'All Years'!D20) -> 0 | G17: =F17*E17*D17*C17 -> 0 | H17: 0.095 | I17: =G17*H17 -> 0 | J17: =G17+I17 -> 0
A18: Other Personnel Subtotal | G18: =SUM(G10:G17) -> 6720
A19: C. Fringe Benefits
G20: =G8+G18 -> 97877.832 | H20: + | I20: =SUM(I4:I19) -> 48843.441 | J20: =SUM(J4:J19) -> 146721.27
A21: Subtotals | G21: Total Salary/Wage | I21: Total Benefits = | J21: Total SWB
A22: Additional Direct Costs | C22: (Enter for EVERY year that applies)
A23: D. Equipment | C23: (Note: Minimum $5,000 per item)
A24: Add description of equipment here… | J24: 0
J25: 0
J26: 0
J27: 0
I28: Total | J28: =SUM(J24:J27) -> 0
A29: E. Travel
A30: 1. Travel to UI for 3 people - Each person will have airfare $500, hotel 2 nights $450, per diem $175, $1,125 each | J30: 3375
A31: 2. Data Analyst - NCURA SPA Level 2 Workshop | J31: 2500
A32: 3.NCURA National Meeting x 3 people | J32: =3045*3 -> 9135
I33: Total | J33: =SUM(J30:J32) -> 15010
A34: F. Participant Support Costs for Students
A35: Number of Participants – Add # to yellow cell to the right | J35: 0
A36: Stipends – Detail here, if applies | J36: 0
A37: Travel – Detail here, if applies | J37: 0
A38: Subsistence – Per diem. Detail here, if applies | J38: 0
A39: Other – PUI Committee Convening - Travel stipends up to $1,250/participant, 8 participants | J39: 10000
I40: Total | J40: =SUM(J35:J39) -> 10000
...

Sheet Year4
A1: Principal Investigator: | C1: =Year1!C1 -> Sylvia Bradshaw | F1: Start Date: | G1: =DATE(YEAR('All Years'!D21)+'All Years'!D18,MONTH('All Years'!D21),DAY('All Years'!D21)) -> 46569 | H1: End Date: | I1: =DATE(YEAR('All Years'!D22)+'All Years'!D18,MONTH('All Years'!D22),DAY('All Years'!D22)) -> 46934 | J1: Year 4
A2: Title: | B2: =Year1!B2 -> NSF GRANTED - University of Idaho
A3: A. Senior Personnel | C3: Role | D3: Months | E3: % Effort | F3: Base Salary | G3: Salary Request | H3: % Fringe | I3: Benefits | J3: Total
A4: =Year1!A4 -> Sylvia Bradshaw | C4: =Year1!C4 -> PI | D4: =12*E4 -> 1.5 | E4: 0.125 | F4: =Year3!F4*(1+'All Years'!E20) -> 125663.61 | G4: =SUM(F4/12)*D4 -> 15707.951 | H4: 0.235 | I4: =(G4*H4)+(21138*E4) -> 6333.6184 | J4: =G4+I4 -> 22041.569
A5: =Year1!A5 -> Katie Gomez | C5: =Year1!C5 -> 0 | D5: =12*E5 -> 1.8 | E5: =Year1!E5 -> 0.15 | F5: =Year3!F5*(1+'All Years'!E20) -> 84139.979 | G5: =SUM(F5/12)*D5 -> 12620.997 | H5: 0.235 | I5: =(G5*H5)+(21138*E5) -> 6136.6343 | J5: =G5+I5 -> 18757.631
A6: =Year1!A6 -> TBD - Data Analyst | C6: =Year1!C6 -> 0 | D6: =12*E6 -> 12 | E6: =Year1!E6 -> 1 | F6: =Year3!F6*(1+'All Years'!E20) -> 65563.62 | G6: =SUM(F6/12)*D6 -> 65563.62 | H6: 0.235 | I6: =(G6*H6)+(21138*E6) -> 36545.451 | J6: =G6+I6 -> 102109.07
A7: =Year1!A7 -> Name here (e.g., co-PI, Sr. Personnel) | C7: =Year1!C7 -> 0 | D7: =12*E7 -> 0 | E7: =Year1!E7 -> 0 | F7: =Year3!F7*(1+'All Years'!E20) -> 0 | G7: =SUM(F7/9)*D7 -> 0 | H7: 0.235 | I7: =G7*H7 -> 0 | J7: =G7+I7 -> 0
A8: Senior Personnel Subtotal | G8: =SUM(G4:G7) -> 93892.567
A9: B. Other Personnel | C9: Role | D9: Months | E9: % Effort | F9: Base Salary | G9: Salary Request | H9: % Fringe | I9: Benefits | J9: Total
A10: =Year1!A10 -> Postdoctoral Scholars (*faculty benefit rate) | C10: =Year1!C10 -> 0 | D10: =12*E10 -> 0 | E10: =Year1!E10 -> 0 | F10: =Year3!F10*(1+'All Years'!E20) -> 0 | G10: =SUM(F10/9)*D10 -> 0 | H10: 0.235 | I10: =G10*H10 -> 0 | J10: =G10+I10 -> 0
A11: =Year1!A11 -> Other Professionals (**staff benefit rate) | C11: =Year1!C11 -> 0 | D11: =12*E11 -> 0 | E11: =Year1!E11 -> 0 | F11: =Year3!F11*(1+'All Years'!E20) -> 0 | G11: =F11*E11 -> 0 | H11: 0.235 | I11: =(G11*H11)+(21138*E11) -> 0 | J11: =G11+I11 -> 0
A12: =Year1!A12 -> Other Professionals (**staff benefit rate) | C12: =Year1!C12 -> 0 | D12: =12*E12 -> 0 | E12: =Year1!E12 -> 0 | F12: =Year3!F12*(1+'All Years'!E20) -> 0 | G12: =F12*E12 -> 0 | H12: 0.235 | I12: =(G12*H12)+(21138*E12) -> 0 | J12: =G12+I12 -> 0
C13: How Many | D13: # of wks | E13: Hrs/wk | F13: Base Rate | G13: Wage Request | H13: % Fringe | I13: Benefits | J13: Total
A14: =Year1!A14 -> Graduate Students (*student benefit rate) | C14: =Year1!C14 -> 0 | D14: =Year1!D14 -> 0 | E14: =Year1!E14 -> 0 | F14: =Year3!F14*(1+'All Years'!E20) -> 0 | G14: =F14*E14*D14*C14 -> 0 | H14: 0.07 | I14: =G14*H14 -> 0 | J14: =G14+I14 -> 0
A15: =Year1!A15 -> Undergraduate Students (*student benefit rate) | C15: =Year1!C15 -> 1 | D15: =Year1!D15 -> 42 | E15: =Year1!E15 -> 10 | F15: 17 | G15: =C15*D15*E15*F15 -> 7140 | H15: 0.07 | I15: =G15*H15 -> 499.8 | J15: =G15+I15 -> 7639.8
A16: =Year1!A16 -> Administrative/Clerical (**non-Student benefit rate) | C16: =Year1!C16 -> 0 | D16: =Year1!D16 -> 0 | E16: =Year1!E16 -> 0 | F16: =Year3!F16*(1+'All Years'!E20) -> 0 | G16: =F16*E16*D16*C16 -> 0 | H16: 0.095 | I16: =G16*H16 -> 0 | J16: =G16+I16 -> 0
A17: =Year1!A17 -> Other (**non-student benefit rate) | C17: =Year1!C17 -> 0 | D17: =Year1!D17 -> 0 | E17: =Year1!E17 -> 0 | F17: =Year3!F17*(1+'All Years'!E20) -> 0 | G17: =F17*E17*D17*C17 -> 0 | H17: 0.095 | I17: =G17*H17 -> 0 | J17: =G17+I17 -> 0
A18: Other Personnel Subtotal | G18: =SUM(G10:G17) -> 7140
A19: C. Fringe Benefits
G20: =G8+G18 -> 101032.57 | H20: + | I20: =SUM(I4:I19) -> 49515.503 | J20: =SUM(J4:J19) -> 150548.07
A21: Subtotals | G21: Total Salary/Wage | I21: Total Benefits = | J21: Total SWB
A22: Additional Direct Costs | C22: (Enter for EVERY year that applies)
A23: D. Equipment | C23: (Note: Minimum $5,000 per item)
A24: Add description of equipment here… | J24: 0
J25: 0
J26: 0
J27: 0
I28: Total | J28: =SUM(J24:J27) -> 0
A29: E. Travel
A30: 1. Travel to UI for 3 people - Each person will have airfare $500, hotel 2 nights $450, per diem $175, $1,125 each | J30: 3375
A31: 2. Data Analyst - NCURA SPA Level 2 Workshop | J31: 2500
A32: 3.NCURA National Meeting x 3 people | J32: =3045*3 -> 9135
I33: Total | J33: =SUM(J30:J32) -> 15010
A34: F. Participant Support Costs for Students
A35: Number of Participants – Add # to yellow cell to the right | J35: 0
A36: Stipends – Detail here, if applies | J36: 0
A37: Travel – Detail here, if applies | J37: 0
A38: Subsistence – Per diem. Detail here, if applies | J38: 0
A39: Other – PUI Committee Convening - Travel stipends up to $1,250/participant, 8 participants | J39: 10000
I40: Total | J40: =SUM(J35:J39) -> 10000
...

Sheet Year 5
A1: Principal Investigator: | C1: =Year1!C1 -> Sylvia Bradshaw | F1: Start Date: | G1: 46935 | H1: End Date: | I1: 47299 | J1: Year 5
A2: Title: | B2: =Year1!B2 -> NSF GRANTED - University of Idaho
A3: A. Senior Personnel | C3: Role | D3: Months | E3: % Effort | F3: Base Salary | G3: Salary Request | H3: % Fringe | I3: Benefits | J3: Total
A4: =Year1!A4 -> Sylvia Bradshaw | C4: =Year1!C4 -> PI | D4: =12*E4 -> 1.5 | E4: 0.125 | F4: =Year4!F4*(1+'All Years'!E20) -> 129433.51 | G4: =SUM(F4/12)*D4 -> 16179.189 | H4: 0.235 | I4: =(G4*H4)+(21138*E4) -> 6444.3594 | J4: =G4+I4 -> 22623.549
A5: =Year1!A5 -> Katie Gomez | C5: =Year1!C5 -> 0 | D5: =12*E5 -> 1.8 | E5: =Year1!E5 -> 0.15 | F5: =Year4!F5*(1+'All Years'!E20) -> 86664.178 | G5: =SUM(F5/12)*D5 -> 12999.627 | H5: 0.235 | I5: =(G5*H5)+(21138*E5) -> 6225.6123 | J5: =G5+I5 -> 19225.239
A6: =Year1!A6 -> TBD - Data Analyst | C6: =Year1!C6 -> 0 | D6: =12*E6 -> 12 | E6: =Year1!E6 -> 1 | F6: =Year4!F6*(1+'All Years'!E20) -> 67530.529 | G6: =SUM(F6/12)*D6 -> 67530.529 | H6: 0.235 | I6: =(G6*H6)+(21138*E6) -> 37007.674 | J6: =G6+I6 -> 104538.2
C7: =Year1!C7 -> 0 | D7: =12*E7 -> 0 | E7: =Year1!E7 -> 0 | F7: =Year3!F7*(1+'All Years'!E20) -> 0 | G7: =SUM(F7/9)*D7 -> 0 | I7: =G7*H7 -> 0 | J7: =G7+I7 -> 0
A8: Senior Personnel Subtotal | G8: =SUM(G4:G7) -> 96709.344
A9: B. Other Personnel | C9: Role | D9: Months | E9: % Effort | F9: Base Salary | G9: Salary Request | H9: % Fringe | I9: Benefits | J9: Total
A10: =Year1!A10 -> Postdoctoral Scholars (*faculty benefit rate) | C10: =Year1!C10 -> 0 | D10: =12*E10 -> 0 | E10: =Year1!E10 -> 0 | F10: =Year3!F10*(1+'All Years'!E20) -> 0 | G10: =SUM(F10/9)*D10 -> 0 | H10: 0.235 | I10: =G10*H10 -> 0 | J10: =G10+I10 -> 0
A11: =Year1!A11 -> Other Professionals (**staff benefit rate) | C11: =Year1!C11 -> 0 | D11: =12*E11 -> 0 | E11: =Year1!E11 -> 0 | F11: =Year3!F11*(1+'All Years'!E20) -> 0 | G11: =F11*E11 -> 0 | H11: 0.235 | I11: =(G11*H11)+(21138*E11) -> 0 | J11: =G11+I11 -> 0
A12: =Year1!A12 -> Other Professionals (**staff benefit rate) | C12: =Year1!C12 -> 0 | D12: =12*E12 -> 0 | E12: =Year1!E12 -> 0 | F12: =Year3!F12*(1+'All Years'!E20) -> 0 | G12: =F12*E12 -> 0 | H12: 0.235 | I12: =(G12*H12)+(21138*E12) -> 0 | J12: =G12+I12 -> 0
C13: How Many | D13: # of wks | E13: Hrs/wk | F13: Base Rate | G13: Wage Request | H13: % Fringe | I13: Benefits | J13: Total
A14: =Year1!A14 -> Graduate Students (*student benefit rate) | C14: =Year1!C14 -> 0 | D14: =Year1!D14 -> 0 | E14: =Year1!E14 -> 0 | F14: =Year3!F14*(1+'All Years'!E20) -> 0 | G14: =F14*E14*D14*C14 -> 0 | H14: 0.07 | I14: =G14*H14 -> 0 | J14: =G14+I14 -> 0
A15: =Year1!A15 -> Undergraduate Students (*student benefit rate) | C15: =Year1!C15 -> 1 | D15: =Year1!D15 -> 42 | E15: =Year1!E15 -> 10 | F15: 18 | G15: =C15*D15*E15*F15 -> 7560 | H15: 0.07 | I15: =G15*H15 -> 529.2 | J15: =G15+I15 -> 8089.2
A16: =Year1!A16 -> Administrative/Clerical (**non-Student benefit rate) | C16: =Year1!C16 -> 0 | D16: =Year1!D16 -> 0 | E16: =Year1!E16 -> 0 | F16: =Year3!F16*(1+'All Years'!E20) -> 0 | G16: =F16*E16*D16*C16 -> 0 | H16: 0.095 | I16: =G16*H16 -> 0 | J16: =G16+I16 -> 0
A17: =Year1!A17 -> Other (**non-student benefit rate) | C17: =Year1!C17 -> 0 | D17: =Year1!D17 -> 0 | E17: =Year1!E17 -> 0 | F17: =Year3!F17*(1+'All Years'!E20) -> 0 | G17: =F17*E17*D17*C17 -> 0 | H17: 0.095 | I17: =G17*H17 -> 0 | J17: =G17+I17 -> 0
A18: Other Personnel Subtotal | G18: =SUM(G10:G17) -> 7560
A19: C. Fringe Benefits
G20: =G8+G18 -> 104269.34 | H20: + | I20: =SUM(I4:I19) -> 50206.846 | J20: =SUM(J4:J19) -> 154476.19
A21: Subtotals | G21: Total Salary/Wage | I21: Total Benefits = | J21: Total SWB
A22: Additional Direct Costs | C22: (Enter for EVERY year that applies)
A23: D. Equipment | C23: (Note: Minimum $5,000 per item)
A24: Add description of equipment here… | J24: 0
J25: 0
J26: 0
J27: 0
I28: Total | J28: =SUM(J24:J27) -> 0
A29: E. Travel
A30: 1. Travel to UI for 3 people - Each person will have airfare $500, hotel 2 nights $450, per diem $175, $1,125 each | J30: 3375
A32: 3.NCURA National Meeting x 3 people | J32: =3045*3 -> 9135
I33: Total | J33: =SUM(J30:J32) -> 12510
A34: F. Participant Support Costs for Students
A35: Number of Participants – Add # to yellow cell to the right | J35: 0
A36: Stipends – Detail here, if applies | J36: 0
A37: Travel – Detail here, if applies | J37: 0
A38: Subsistence – Per diem. Detail here, if applies | J38: 0
A39: Other – PUI Committee Convening - Travel stipends up to $1,250/participant, 8 participants | J39: 10000
I40: Total | J40: =SUM(J35:J39) -> 10000
A41: G. Other Direct Costs
...

Sheet All Years
A1: PERSONNEL DIRECT COSTS | B1: Year 1 | C1: Year 2 | D1: Year 3 | E1: Year 4 | F1: Year 5 | G1: All Years
A2: =Year1!A3 -> A. Senior Personnel | B2: =Year1!G8 -> 77300 | C2: =Year2!G8 -> 79619 | D2: =Year3!G8 -> 91157.832 | E2: =Year4!G8 -> 93892.567 | F2: ='Year 5'!G8 -> 96709.344 | G2: =SUM(B2:F2) -> 438678.74
A3: =Year1!A9 -> B. Other Personnel | B3: =Year1!G18 -> 5880 | C3: =Year2!G18 -> 6300 | D3: =Year3!G18 -> 6720 | E3: =Year4!G18 -> 7140 | F3: ='Year 5'!G18 -> 7560 | G3: =SUM(B3:F3) -> 33600
A4: Total SW (A-B) | B4: =SUM(B2:B3) -> 83180 | C4: =SUM(C2:C3) -> 85919 | D4: =SUM(D2:D3) -> 97877.832 | E4: =SUM(E2:E3) -> 101032.57 | F4: =SUM(F2:F3) -> 104269.34 | G4: =SUM(G2:G3) -> 472278.74
A5: =Year1!A19 -> C. Fringe Benefits | B5: =Year1!I20 -> 43942.7 | C5: =Year2!I20 -> 44517.065 | D5: =Year3!I20 -> 48843.441 | E5: =Year4!I20 -> 49515.503 | F5: ='Year 5'!I20 -> 50206.846 | G5: =SUM(B5:F5) -> 237025.55
A6: Total SWB (A-C) | B6: =B4+B5 -> 127122.7 | C6: =C4+C5 -> 130436.07 | D6: =D4+D5 -> 146721.27 | E6: =E4+E5 -> 150548.07 | F6: =F4+F5 -> 154476.19 | G6: =G4+G5 -> 709304.3
A7: ADDITIONAL DIRECT COSTS
A8: =Year1!A23 -> D. Equipment | B8: =Year1!J28 -> 0 | C8: =Year2!J28 -> 0 | D8: =Year3!J28 -> 0 | E8: =Year4!J28 -> 0 | F8: ='Year 5'!J24 -> 0 | G8: =SUM(B8:F8) -> 0
A9: =Year1!A29 -> E. Travel | B9: =Year1!J33 -> 8375 | C9: =Year2!J33 -> 8375 | D9: =Year3!J33 -> 15010 | E9: =Year4!J33 -> 15010 | F9: ='Year 5'!J33 -> 12510 | G9: =SUM(B9:F9) -> 59280
A10: =Year1!A34 -> F. Participant Support Costs | B10: =Year1!J40 -> 10000 | C10: =Year2!J40 -> 10000 | D10: =Year3!J40 -> 10000 | E10: =Year4!J40 -> 10000 | F10: ='Year 5'!J39 -> 10000 | G10: =SUM(B10:F10) -> 50000
A11: =Year1!A41 -> G. Other Direct Costs | B11: =Year1!J51 -> 5000 | C11: =Year2!J51 -> 0 | D11: =Year3!J51 -> 0 | E11: =Year4!J51 -> 0 | F11: ='Year 5'!J51 -> 0 | G11: =SUM(B11:F11) -> 5000
A12: =Year1!A52 -> H. Total Direct Costs (A-G) | B12: =Year1!J52 -> 150497.7 | C12: =Year2!J52 -> 148811.07 | D12: =Year3!J52 -> 171731.27 | E12: =Year4!J52 -> 175558.07 | F12: ='Year 5'!J52 -> 176986.19 | G12: =SUM(B12:F12) -> 823584.3
A13: =Year1!A54 -> I. Indirect Costs | B13: =Year1!J54 -> 57205.215 | C13: =Year2!J54 -> 58696.229 | D13: =Year3!J54 -> 66024.573 | E13: =Year4!J54 -> 67746.632 | F13: ='Year 5'!J54 -> 69514.286 | G13: =SUM(B13:F13) -> 319186.93
A14: =Year1!A56 -> J. Total Amount Requested (H + I) | B14: =SUM(B12:B13) -> 207702.92 | C14: =SUM(C12:C13) -> 207507.29 | D14: =SUM(D12:D13) -> 237755.85 | E14: =SUM(E12:E13) -> 243304.7 | F14: =SUM(F12:F13) -> 246500.48 | G14: =SUM(G12:G13) -> 1142771.2
B18: 1 | C18: 1 | D18: 1 | E18: 1 | F18: 1 | G18: 1
B19: Salary Increase | C19: Salary Increase | D19: Salary Increase | E19: Salary Increase | F19: Salary Increase | G19: Salary Increase
C20: 0.03 | D20: 0.03 | E20: 0.03 | F20: 0.03 | G20: 0.03
B21: =Year1!G1 -> 45474 | C21: =Year2!G1 -> 45839 | D21: =Year3!G1 -> 46204 | E21: =Year4!G1 -> 46569 | F21: ='Year 5'!G1 -> 46935
B22: =Year1!I1 -> 45838 | C22: =Year2!I1 -> 46203 | D22: =Year3!I1 -> 46568 | E22: =Year4!I1 -> 46934 | F22: ='Year 5'!I1 -> 47299
A25: *Note: This electronic form contains formulas that may be corrupted when adding or deleting rows, or deleting certain cells.
